Workbook

Sheet ⚙️ BEÁLLÍTÁSOK
A1: ⚙️ SIROTECH – BEÁLLÍTÁSOK | Kék cellák szabadon módosíthatók
A2: Minden ár nettó Ft. Az összes lap innen számol – csak itt kell módosítani.
A4: REZSI ÉS OVERHEAD KALKULÁCIÓ (bérköltség + fix rezsi fedezete)
A5: Az overhead szorzó azt fejezi ki, hogy a ténylegesen helyszínen dolgozó órákra mekkora fedezetet kell termelni a háttérben dolgozók bérére és a cég fix költségeire. Pl. 1,45 = 45% rezsi a munkadíjra rakva.
A6: Overhead / rezsi szorzó (alapértelmezett) | B6: 1.85 | C6: pl. 1,45 = 45% rezsi felár a termelő munkára
A7: Fix havi rezsiköltség (Ft) – tájékoztató | B7: 1450000 | C7: bérek + iroda + szoftverek + járművek
A8: Havi termelő munkaórák száma (cégszinten) | B8: 780 | C8: termelő munka összesen / hó
A9: Számított rezsi / óra | B9: =B7/B8 -> 1858.9744 | C9: fix rezsi / termelő óra (tájékoztató)
A11: BELSŐ ÓRADÍJAK – HELYSZÍNEN DOLGOZÓ MUNKAVÁLLALÓI COST (Ft/óra)
A12: Ez a tényleges bérköltség + járulékok / óra. Soha nem kommunikálod kifelé. Az ajánlati ár = belső óradíj × overhead × ügyfél szorzó.
A13: IT – üzemeltetés, hálózat, helpdesk | B13: 6200 | C13: munkavállalói bérköltség/óra
A14: IT – szoftver, fejlesztés, architektúra | B14: 9500
A15: Biztonságtechnika – szerelő | B15: 6800
A16: Biztonságtechnika – tervező, PM | B16: 7500
A17: Tűzvédelem – szerelő | B17: 6200
A18: Tűzvédelem – tervező, dokumentáló | B18: 8200
A19: Villanyszerelő – általános | B19: 6000
A20: Villanyszerelő – ipari / EV töltő | B20: 7000
A21: Projektmenedzsment, koordináció | B21: 8500
A22: Tanácsadás, audit, tréning | B22: 11500
A24: KALKULÁLT AJÁNLATI ÓRADÍJAK (belső cost × overhead szorzó) → ez az alap lista óradíj
A25: Ezeket használja az Árazási Mátrix és az Alvállalkozói lap kiindulópontként. Ügyfél szorzó még erre jön rá.
A26: IT – üzemeltetés, hálózat, helpdesk | B26: =B13*B6 -> 11470 | C26: ← belső cost × overhead
A27: IT – szoftver, fejlesztés, architektúra | B27: =B14*B6 -> 17575 | C27: ← belső cost × overhead
A28: Biztonságtechnika – szerelő | B28: =B15*B6 -> 12580 | C28: ← belső cost × overhead
A29: Biztonságtechnika – tervező, PM | B29: =B16*B6 -> 13875 | C29: ← belső cost × overhead
A30: Tűzvédelem – szerelő | B30: =B17*B6 -> 11470 | C30: ← belső cost × overhead
A31: Tűzvédelem – tervező, dokumentáló | B31: =B18*B6 -> 15170 | C31: ← belső cost × overhead
A32: Villanyszerelő – általános | B32: =B19*B6 -> 11100 | C32: ← belső cost × overhead
A33: Villanyszerelő – ipari / EV töltő | B33: =B20*B6 -> 12950 | C33: ← belső cost × overhead
A34: Projektmenedzsment, koordináció | B34: =B21*B6 -> 15725 | C34: ← belső cost × overhead
A35: Tanácsadás, audit, tréning | B35: =B22*B6 -> 21275 | C35: ← belső cost × overhead
A37: ÜGYFÉL KATEGÓRIA SZORZÓK (az alap kalkulált listaárra kerül rá)
A38: A kalkulált óradíj × ügyfél szorzó = végleges ajánlati ár. Az 1 éves KKV a referenciapont (×1,00).
A39: Magánszemély (B2C) | B39: 1 | C39: alap listaár
A40: KKV – eseti, nincs keretszerz. | B40: 1.15 | C40: rugalmassági felár a kiszámíthatatlanság miatt
A41: KKV – keretszerz. 6 hónap | B41: 1.08
A42: KKV – keretszerz. 1 év (REFERENCIA) | B42: 1 | C42: ← minden más ehhez képest értendő
A43: KKV – keretszerz. 2 év | B43: 0.93
A44: Nagyvállalat / intézmény (eseti) | B44: 1.25 | C44: hosszú döntési ciklus, admin kompenzáció
...

Sheet 📋 ÁRAZÁSI MÁTRIX
A1: 📋 SIROTECH – TELJES ÁRAZÁSI MÁTRIX | Nettó Ft + 27% ÁFA | Anyagköltség minden esetben külön
A2: Kék cella = belső alap ár (módosítható) │ Zöld szöveg = automatikus formula │ Ahol 'egyedi' áll → Kalkulátor lapon számold │ Overhead beépítve a Beállítások lapon
B3: Szolgáltatás / Tétel | C3: Egység | D3: Belső alap ár (Ft) | E3: Magán- személy | F3: KKV eseti | G3: KKV 6 hónap | H3: KKV 1 év (ALAP) | I3: KKV 2 év | J3: Nagyvállalat / int. | K3: Megjegyzés
B4: Szorzók → | D4: belső alap | E4: ='⚙️ BEÁLLÍTÁSOK'!B39 -> 1 | F4: ='⚙️ BEÁLLÍTÁSOK'!B40 -> 1.15 | G4: ='⚙️ BEÁLLÍTÁSOK'!B41 -> 1.08 | H4: ='⚙️ BEÁLLÍTÁSOK'!B42 -> 1 | I4: ='⚙️ BEÁLLÍTÁSOK'!B43 -> 0.93 | J4: ='⚙️ BEÁLLÍTÁSOK'!B44 -> 1.25
A5: 🖥️ IT RENDSZERÜZEMELTETÉS – MSP havidíjas csomagok
A6: Csomagban: távfelügyelet, vírusvédelem, frissítések, havi állapotjelentés, email+tel. support (munkaidőben), dedikált kapcsolattartó, dokumentált beavatkozások.
B7: Mikro csomag – 1–3 munkaállomás, csak remote | C7: hó | D7: 24000 | E7: =ROUND(D7*'⚙️ BEÁLLÍTÁSOK'!B39/100,0)*100 -> 24000 | F7: =ROUND(D7*'⚙️ BEÁLLÍTÁSOK'!B40/100,0)*100 -> 27600 | G7: =ROUND(D7*'⚙️ BEÁLLÍTÁSOK'!B41/100,0)*100 -> 25900 | H7: =ROUND(D7*'⚙️ BEÁLLÍTÁSOK'!B42/100,0)*100 -> 24000 | I7: =ROUND(D7*'⚙️ BEÁLLÍTÁSOK'!B43/100,0)*100 -> 22300 | J7: =ROUND(D7*'⚙️ BEÁLLÍTÁSOK'!B44/100,0)*100 -> 30000 | K7: Ideális 1-3 fős irodának
B8: Alap csomag – 4–8 gép, csak remote | C8: hó | D8: 52000 | E8: =ROUND(D8*'⚙️ BEÁLLÍTÁSOK'!B39/100,0)*100 -> 52000 | F8: =ROUND(D8*'⚙️ BEÁLLÍTÁSOK'!B40/100,0)*100 -> 59800 | G8: =ROUND(D8*'⚙️ BEÁLLÍTÁSOK'!B41/100,0)*100 -> 56200 | H8: =ROUND(D8*'⚙️ BEÁLLÍTÁSOK'!B42/100,0)*100 -> 52000 | I8: =ROUND(D8*'⚙️ BEÁLLÍTÁSOK'!B43/100,0)*100 -> 48400 | J8: =ROUND(D8*'⚙️ BEÁLLÍTÁSOK'!B44/100,0)*100 -> 65000
B9: Kis csomag – 9–15 gép, remote + havi 1 kiszállás | C9: hó | D9: 98000 | E9: =ROUND(D9*'⚙️ BEÁLLÍTÁSOK'!B39/100,0)*100 -> 98000 | F9: =ROUND(D9*'⚙️ BEÁLLÍTÁSOK'!B40/100,0)*100 -> 112700 | G9: =ROUND(D9*'⚙️ BEÁLLÍTÁSOK'!B41/100,0)*100 -> 105800 | H9: =ROUND(D9*'⚙️ BEÁLLÍTÁSOK'!B42/100,0)*100 -> 98000 | I9: =ROUND(D9*'⚙️ BEÁLLÍTÁSOK'!B43/100,0)*100 -> 91100 | J9: =ROUND(D9*'⚙️ BEÁLLÍTÁSOK'!B44/100,0)*100 -> 122500
B10: Közép csomag – 16–30 gép, havi 2 kiszállás | C10: hó | D10: 175000 | E10: =ROUND(D10*'⚙️ BEÁLLÍTÁSOK'!B39/100,0)*100 -> 175000 | F10: =ROUND(D10*'⚙️ BEÁLLÍTÁSOK'!B40/100,0)*100 -> 201200 | G10: =ROUND(D10*'⚙️ BEÁLLÍTÁSOK'!B41/100,0)*100 -> 189000 | H10: =ROUND(D10*'⚙️ BEÁLLÍTÁSOK'!B42/100,0)*100 -> 175000 | I10: =ROUND(D10*'⚙️ BEÁLLÍTÁSOK'!B43/100,0)*100 -> 162800 | J10: =ROUND(D10*'⚙️ BEÁLLÍTÁSOK'!B44/100,0)*100 -> 218800
B11: Nagy csomag – 30+ gép, egyedi SLA | C11: hó | D11: egyedi | E11: – | F11: – | G11: – | H11: – | I11: – | J11: – | K11: Egyedi árajánlat
B12: Szerverszoba pótdíj (havidíj) | C12: hó | D12: 25000 | E12: =ROUND(D12*'⚙️ BEÁLLÍTÁSOK'!B39/100,0)*100 -> 25000 | F12: =ROUND(D12*'⚙️ BEÁLLÍTÁSOK'!B40/100,0)*100 -> 28700 | G12: =ROUND(D12*'⚙️ BEÁLLÍTÁSOK'!B41/100,0)*100 -> 27000 | H12: =ROUND(D12*'⚙️ BEÁLLÍTÁSOK'!B42/100,0)*100 -> 25000 | I12: =ROUND(D12*'⚙️ BEÁLLÍTÁSOK'!B43/100,0)*100 -> 23300 | J12: =ROUND(D12*'⚙️ BEÁLLÍTÁSOK'!B44/100,0)*100 -> 31300 | K12: Rack, UPS, hőmérséklet monitorozás
B13: Kiszállási alap díj (min. egység) | C13: alkalom | D13: 15000 | E13: =ROUND(D13*'⚙️ BEÁLLÍTÁSOK'!B39/100,0)*100 -> 15000 | F13: =ROUND(D13*'⚙️ BEÁLLÍTÁSOK'!B40/100,0)*100 -> 17300 | G13: =ROUND(D13*'⚙️ BEÁLLÍTÁSOK'!B41/100,0)*100 -> 16200 | H13: =ROUND(D13*'⚙️ BEÁLLÍTÁSOK'!B42/100,0)*100 -> 15000 | I13: =ROUND(D13*'⚙️ BEÁLLÍTÁSOK'!B43/100,0)*100 -> 14000 | J13: =ROUND(D13*'⚙️ BEÁLLÍTÁSOK'!B44/100,0)*100 -> 18800 | K13: Kiszállás + 1 óra munkadíj
B14: Rendkívüli kiszállás (munkaidőn túl) | C14: alkalom | D14: 24000 | E14: =ROUND(D14*'⚙️ BEÁLLÍTÁSOK'!B39/100,0)*100 -> 24000 | F14: =ROUND(D14*'⚙️ BEÁLLÍTÁSOK'!B40/100,0)*100 -> 27600 | G14: =ROUND(D14*'⚙️ BEÁLLÍTÁSOK'!B41/100,0)*100 -> 25900 | H14: =ROUND(D14*'⚙️ BEÁLLÍTÁSOK'!B42/100,0)*100 -> 24000 | I14: =ROUND(D14*'⚙️ BEÁLLÍTÁSOK'!B43/100,0)*100 -> 22300 | J14: =ROUND(D14*'⚙️ BEÁLLÍTÁSOK'!B44/100,0)*100 -> 30000 | K14: Sürgősségi szorzó alapján
A15: ▸ OPERÁCIÓS RENDSZER ÉS SZOFTVER
B16: Windows frissítések kezelése és tesztelése | C16: gép/hó | D16: 1200 | E16: =ROUND(D16*'⚙️ BEÁLLÍTÁSOK'!B39/100,0)*100 -> 1200 | F16: =ROUND(D16*'⚙️ BEÁLLÍTÁSOK'!B40/100,0)*100 -> 1400 | G16: =ROUND(D16*'⚙️ BEÁLLÍTÁSOK'!B41/100,0)*100 -> 1300 | H16: =ROUND(D16*'⚙️ BEÁLLÍTÁSOK'!B42/100,0)*100 -> 1200 | I16: =ROUND(D16*'⚙️ BEÁLLÍTÁSOK'!B43/100,0)*100 -> 1100 | J16: =ROUND(D16*'⚙️ BEÁLLÍTÁSOK'!B44/100,0)*100 -> 1500 | K16: MSP csomagba beleszámítható
B17: Windows aktiválás, licenckezelés | C17: db | D17: 6000 | E17: =ROUND(D17*'⚙️ BEÁLLÍTÁSOK'!B39/100,0)*100 -> 6000 | F17: =ROUND(D17*'⚙️ BEÁLLÍTÁSOK'!B40/100,0)*100 -> 6900 | G17: =ROUND(D17*'⚙️ BEÁLLÍTÁSOK'!B41/100,0)*100 -> 6500 | H17: =ROUND(D17*'⚙️ BEÁLLÍTÁSOK'!B42/100,0)*100 -> 6000 | I17: =ROUND(D17*'⚙️ BEÁLLÍTÁSOK'!B43/100,0)*100 -> 5600 | J17: =ROUND(D17*'⚙️ BEÁLLÍTÁSOK'!B44/100,0)*100 -> 7500
B18: Windows frissítés letiltása / ütemezése (gyárban) | C18: gép | D18: 5000 | E18: =ROUND(D18*'⚙️ BEÁLLÍTÁSOK'!B39/100,0)*100 -> 5000 | F18: =ROUND(D18*'⚙️ BEÁLLÍTÁSOK'!B40/100,0)*100 -> 5800 | G18: =ROUND(D18*'⚙️ BEÁLLÍTÁSOK'!B41/100,0)*100 -> 5400 | H18: =ROUND(D18*'⚙️ BEÁLLÍTÁSOK'!B42/100,0)*100 -> 5000 | I18: =ROUND(D18*'⚙️ BEÁLLÍTÁSOK'!B43/100,0)*100 -> 4700 | J18: =ROUND(D18*'⚙️ BEÁLLÍTÁSOK'!B44/100,0)*100 -> 6300
B19: Office telepítés és aktiválás (M365 vagy standalone) | C19: gép | D19: 5500 | E19: =ROUND(D19*'⚙️ BEÁLLÍTÁSOK'!B39/100,0)*100 -> 5500 | F19: =ROUND(D19*'⚙️ BEÁLLÍTÁSOK'!B40/100,0)*100 -> 6300 | G19: =ROUND(D19*'⚙️ BEÁLLÍTÁSOK'!B41/100,0)*100 -> 5900 | H19: =ROUND(D19*'⚙️ BEÁLLÍTÁSOK'!B42/100,0)*100 -> 5500 | I19: =ROUND(D19*'⚙️ BEÁLLÍTÁSOK'!B43/100,0)*100 -> 5100 | J19: =ROUND(D19*'⚙️ BEÁLLÍTÁSOK'!B44/100,0)*100 -> 6900
B20: M365 / Google Workspace adminisztráció | C20: óra | D20: egyedi | E20: – | F20: – | G20: – | H20: – | I20: – | J20: – | K20: → IT óradíj alapján (Kalkulátor)
B21: Meghajtók, jogosultságok, mappastruktúra kialakítása | C21: projekt | D21: 26000 | E21: =ROUND(D21*'⚙️ BEÁLLÍTÁSOK'!B39/100,0)*100 -> 26000 | F21: =ROUND(D21*'⚙️ BEÁLLÍTÁSOK'!B40/100,0)*100 -> 29900 | G21: =ROUND(D21*'⚙️ BEÁLLÍTÁSOK'!B41/100,0)*100 -> 28100 | H21: =ROUND(D21*'⚙️ BEÁLLÍTÁSOK'!B42/100,0)*100 -> 26000 | I21: =ROUND(D21*'⚙️ BEÁLLÍTÁSOK'!B43/100,0)*100 -> 24200 | J21: =ROUND(D21*'⚙️ BEÁLLÍTÁSOK'!B44/100,0)*100 -> 32500
B22: Felhasználói fiókok kezelése (létrehozás/törlés/jelszó) | C22: db | D22: 3500 | E22: =ROUND(D22*'⚙️ BEÁLLÍTÁSOK'!B39/100,0)*100 -> 3500 | F22: =ROUND(D22*'⚙️ BEÁLLÍTÁSOK'!B40/100,0)*100 -> 4000 | G22: =ROUND(D22*'⚙️ BEÁLLÍTÁSOK'!B41/100,0)*100 -> 3800 | H22: =ROUND(D22*'⚙️ BEÁLLÍTÁSOK'!B42/100,0)*100 -> 3500 | I22: =ROUND(D22*'⚙️ BEÁLLÍTÁSOK'!B43/100,0)*100 -> 3300 | J22: =ROUND(D22*'⚙️ BEÁLLÍTÁSOK'!B44/100,0)*100 -> 4400
B23: Szoftver telepítés / eltávolítás | C23: db | D23: 3000 | E23: =ROUND(D23*'⚙️ BEÁLLÍTÁSOK'!B39/100,0)*100 -> 3000 | F23: =ROUND(D23*'⚙️ BEÁLLÍTÁSOK'!B40/100,0)*100 -> 3400 | G23: =ROUND(D23*'⚙️ BEÁLLÍTÁSOK'!B41/100,0)*100 -> 3200 | H23: =ROUND(D23*'⚙️ BEÁLLÍTÁSOK'!B42/100,0)*100 -> 3000 | I23: =ROUND(D23*'⚙️ BEÁLLÍTÁSOK'!B43/100,0)*100 -> 2800 | J23: =ROUND(D23*'⚙️ BEÁLLÍTÁSOK'!B44/100,0)*100 -> 3800
B24: Nyomtatók hálózati megosztása, konfigurálása | C24: db | D24: 7500 | E24: =ROUND(D24*'⚙️ BEÁLLÍTÁSOK'!B39/100,0)*100 -> 7500 | F24: =ROUND(D24*'⚙️ BEÁLLÍTÁSOK'!B40/100,0)*100 -> 8600 | G24: =ROUND(D24*'⚙️ BEÁLLÍTÁSOK'!B41/100,0)*100 -> 8100 | H24: =ROUND(D24*'⚙️ BEÁLLÍTÁSOK'!B42/100,0)*100 -> 7500 | I24: =ROUND(D24*'⚙️ BEÁLLÍTÁSOK'!B43/100,0)*100 -> 7000 | J24: =ROUND(D24*'⚙️ BEÁLLÍTÁSOK'!B44/100,0)*100 -> 9400
B25: E-mail konfiguráció (Outlook, Thunderbird, mobilon) | C25: fiók | D25: 5000 | E25: =ROUND(D25*'⚙️ BEÁLLÍTÁSOK'!B39/100,0)*100 -> 5000 | F25: =ROUND(D25*'⚙️ BEÁLLÍTÁSOK'!B40/100,0)*100 -> 5800 | G25: =ROUND(D25*'⚙️ BEÁLLÍTÁSOK'!B41/100,0)*100 -> 5400 | H25: =ROUND(D25*'⚙️ BEÁLLÍTÁSOK'!B42/100,0)*100 -> 5000 | I25: =ROUND(D25*'⚙️ BEÁLLÍTÁSOK'!B43/100,0)*100 -> 4700 | J25: =ROUND(D25*'⚙️ BEÁLLÍTÁSOK'!B44/100,0)*100 -> 6300
B26: Startup optimalizálás (lassú boot) | C26: gép | D26: 6500 | E26: =ROUND(D26*'⚙️ BEÁLLÍTÁSOK'!B39/100,0)*100 -> 6500 | F26: =ROUND(D26*'⚙️ BEÁLLÍTÁSOK'!B40/100,0)*100 -> 7500 | G26: =ROUND(D26*'⚙️ BEÁLLÍTÁSOK'!B41/100,0)*100 -> 7000 | H26: =ROUND(D26*'⚙️ BEÁLLÍTÁSOK'!B42/100,0)*100 -> 6500 | I26: =ROUND(D26*'⚙️ BEÁLLÍTÁSOK'!B43/100,0)*100 -> 6000 | J26: =ROUND(D26*'⚙️ BEÁLLÍTÁSOK'!B44/100,0)*100 -> 8100
B27: Lemez tisztítás, SSD optimalizálás | C27: gép | D27: 5000 | E27: =ROUND(D27*'⚙️ BEÁLLÍTÁSOK'!B39/100,0)*100 -> 5000 | F27: =ROUND(D27*'⚙️ BEÁLLÍTÁSOK'!B40/100,0)*100 -> 5800 | G27: =ROUND(D27*'⚙️ BEÁLLÍTÁSOK'!B41/100,0)*100 -> 5400 | H27: =ROUND(D27*'⚙️ BEÁLLÍTÁSOK'!B42/100,0)*100 -> 5000 | I27: =ROUND(D27*'⚙️ BEÁLLÍTÁSOK'!B43/100,0)*100 -> 4700 | J27: =ROUND(D27*'⚙️ BEÁLLÍTÁSOK'!B44/100,0)*100 -> 6300
A28: ▸ BIZTONSÁG ÉS VÉDELEM
B29: Vírusvédelem telepítés és konfiguráció | C29: gép | D29: 7000 | E29: =ROUND(D29*'⚙️ BEÁLLÍTÁSOK'!B39/100,0)*100 -> 7000 | F29: =ROUND(D29*'⚙️ BEÁLLÍTÁSOK'!B40/100,0)*100 -> 8000 | G29: =ROUND(D29*'⚙️ BEÁLLÍTÁSOK'!B41/100,0)*100 -> 7600 | H29: =ROUND(D29*'⚙️ BEÁLLÍTÁSOK'!B42/100,0)*100 -> 7000 | I29: =ROUND(D29*'⚙️ BEÁLLÍTÁSOK'!B43/100,0)*100 -> 6500 | J29: =ROUND(D29*'⚙️ BEÁLLÍTÁSOK'!B44/100,0)*100 -> 8800
B30: Szoftvertűzfal konfiguráció, szabályok | C30: rendszer | D30: 13000 | E30: =ROUND(D30*'⚙️ BEÁLLÍTÁSOK'!B39/100,0)*100 -> 13000 | F30: =ROUND(D30*'⚙️ BEÁLLÍTÁSOK'!B40/100,0)*100 -> 14900 | G30: =ROUND(D30*'⚙️ BEÁLLÍTÁSOK'!B41/100,0)*100 -> 14000 | H30: =ROUND(D30*'⚙️ BEÁLLÍTÁSOK'!B42/100,0)*100 -> 13000 | I30: =ROUND(D30*'⚙️ BEÁLLÍTÁSOK'!B43/100,0)*100 -> 12100 | J30: =ROUND(D30*'⚙️ BEÁLLÍTÁSOK'!B44/100,0)*100 -> 16300
B31: BitLocker / meghajtótitkosítás beállítása | C31: gép | D31: 7500 | E31: =ROUND(D31*'⚙️ BEÁLLÍTÁSOK'!B39/100,0)*100 -> 7500 | F31: =ROUND(D31*'⚙️ BEÁLLÍTÁSOK'!B40/100,0)*100 -> 8600 | G31: =ROUND(D31*'⚙️ BEÁLLÍTÁSOK'!B41/100,0)*100 -> 8100 | H31: =ROUND(D31*'⚙️ BEÁLLÍTÁSOK'!B42/100,0)*100 -> 7500 | I31: =ROUND(D31*'⚙️ BEÁLLÍTÁSOK'!B43/100,0)*100 -> 7000 | J31: =ROUND(D31*'⚙️ BEÁLLÍTÁSOK'!B44/100,0)*100 -> 9400
B32: Jelszókezelő bevezetése (céges szinten) | C32: projekt | D32: 26000 | E32: =ROUND(D32*'⚙️ BEÁLLÍTÁSOK'!B39/100,0)*100 -> 26000 | F32: =ROUND(D32*'⚙️ BEÁLLÍTÁSOK'!B40/100,0)*100 -> 29900 | G32: =ROUND(D32*'⚙️ BEÁLLÍTÁSOK'!B41/100,0)*100 -> 28100 | H32: =ROUND(D32*'⚙️ BEÁLLÍTÁSOK'!B42/100,0)*100 -> 26000 | I32: =ROUND(D32*'⚙️ BEÁLLÍTÁSOK'!B43/100,0)*100 -> 24200 | J32: =ROUND(D32*'⚙️ BEÁLLÍTÁSOK'!B44/100,0)*100 -> 32500
B33: Kétlépéses hitelesítés (2FA) beállítása | C33: gép | D33: 5000 | E33: =ROUND(D33*'⚙️ BEÁLLÍTÁSOK'!B39/100,0)*100 -> 5000 | F33: =ROUND(D33*'⚙️ BEÁLLÍTÁSOK'!B40/100,0)*100 -> 5800 | G33: =ROUND(D33*'⚙️ BEÁLLÍTÁSOK'!B41/100,0)*100 -> 5400 | H33: =ROUND(D33*'⚙️ BEÁLLÍTÁSOK'!B42/100,0)*100 -> 5000 | I33: =ROUND(D33*'⚙️ BEÁLLÍTÁSOK'!B43/100,0)*100 -> 4700 | J33: =ROUND(D33*'⚙️ BEÁLLÍTÁSOK'!B44/100,0)*100 -> 6300
B34: Adatmentés (backup) konfiguráció és tesztelés | C34: rendszer | D34: 20000 | E34: =ROUND(D34*'⚙️ BEÁLLÍTÁSOK'!B39/100,0)*100 -> 20000 | F34: =ROUND(D34*'⚙️ BEÁLLÍTÁSOK'!B40/100,0)*100 -> 23000 | G34: =ROUND(D34*'⚙️ BEÁLLÍTÁSOK'!B41/100,0)*100 -> 21600 | H34: =ROUND(D34*'⚙️ BEÁLLÍTÁSOK'!B42/100,0)*100 -> 20000 | I34: =ROUND(D34*'⚙️ BEÁLLÍTÁSOK'!B43/100,0)*100 -> 18600 | J34: =ROUND(D34*'⚙️ BEÁLLÍTÁSOK'!B44/100,0)*100 -> 25000
B35: Incidens kezelés, fertőzés utáni helyreállítás | C35: óra | D35: egyedi | E35: – | F35: – | G35: – | H35: – | I35: – | J35: – | K35: → IT óradíj × sürgősségi szorzó
A36: ▸ SZERVER ÉS INFRASTRUKTÚRA – pótdíjak (havi)
B37: Szerver felügyelet (rack / tower) | C37: db/hó | D37: 14000 | E37: =ROUND(D37*'⚙️ BEÁLLÍTÁSOK'!B39/100,0)*100 -> 14000 | F37: =ROUND(D37*'⚙️ BEÁLLÍTÁSOK'!B40/100,0)*100 -> 16100 | G37: =ROUND(D37*'⚙️ BEÁLLÍTÁSOK'!B41/100,0)*100 -> 15100 | H37: =ROUND(D37*'⚙️ BEÁLLÍTÁSOK'!B42/100,0)*100 -> 14000 | I37: =ROUND(D37*'⚙️ BEÁLLÍTÁSOK'!B43/100,0)*100 -> 13000 | J37: =ROUND(D37*'⚙️ BEÁLLÍTÁSOK'!B44/100,0)*100 -> 17500
B38: NAS felügyelet | C38: db/hó | D38: 9000 | E38: =ROUND(D38*'⚙️ BEÁLLÍTÁSOK'!B39/100,0)*100 -> 9000 | F38: =ROUND(D38*'⚙️ BEÁLLÍTÁSOK'!B40/100,0)*100 -> 10400 | G38: =ROUND(D38*'⚙️ BEÁLLÍTÁSOK'!B41/100,0)*100 -> 9700 | H38: =ROUND(D38*'⚙️ BEÁLLÍTÁSOK'!B42/100,0)*100 -> 9000 | I38: =ROUND(D38*'⚙️ BEÁLLÍTÁSOK'!B43/100,0)*100 -> 8400 | J38: =ROUND(D38*'⚙️ BEÁLLÍTÁSOK'!B44/100,0)*100 -> 11300
B39: Tűzfal appliance felügyelet | C39: db/hó | D39: 11000 | E39: =ROUND(D39*'⚙️ BEÁLLÍTÁSOK'!B39/100,0)*100 -> 11000 | F39: =ROUND(D39*'⚙️ BEÁLLÍTÁSOK'!B40/100,0)*100 -> 12600 | G39: =ROUND(D39*'⚙️ BEÁLLÍTÁSOK'!B41/100,0)*100 -> 11900 | H39: =ROUND(D39*'⚙️ BEÁLLÍTÁSOK'!B42/100,0)*100 -> 11000 | I39: =ROUND(D39*'⚙️ BEÁLLÍTÁSOK'!B43/100,0)*100 -> 10200 | J39: =ROUND(D39*'⚙️ BEÁLLÍTÁSOK'!B44/100,0)*100 -> 13800
B40: Menedzselt switch felügyelet | C40: db/hó | D40: 8000 | E40: =ROUND(D40*'⚙️ BEÁLLÍTÁSOK'!B39/100,0)*100 -> 8000 | F40: =ROUND(D40*'⚙️ BEÁLLÍTÁSOK'!B40/100,0)*100 -> 9200 | G40: =ROUND(D40*'⚙️ BEÁLLÍTÁSOK'!B41/100,0)*100 -> 8600 | H40: =ROUND(D40*'⚙️ BEÁLLÍTÁSOK'!B42/100,0)*100 -> 8000 | I40: =ROUND(D40*'⚙️ BEÁLLÍTÁSOK'!B43/100,0)*100 -> 7400 | J40: =ROUND(D40*'⚙️ BEÁLLÍTÁSOK'!B44/100,0)*100 -> 10000
...

Sheet 🤝 ALVÁLLALKOZÓI DÍJAK
A1: 🤝 SIROTECH – ALVÁLLALKOZÓI DÍJTÁBLÁZAT | Nettó Ft/óra | Óradíjas elszámolás főkategóriánként
A2: Két helyzet: (A) Napibéres jelenlét – bemegyek, ott vagyok mint egy dolgozó │ (B) Projekt alapú – saját projekt, alvállalkozói minőségben │ Mindkettő: óradíjas, fél/1/2 éves sávos. Rezsi és overhead beépítve.
A3: Kategória / Szerepkör | B3: Fél éves szerz. (Ft/óra) | C3: 1 éves szerz. (Ft/óra) | D3: 2 éves szerz. (Ft/óra) | E3: Keretszerz. nélkül (Ft/óra) | F3: Megjegyzés / Tartalom
A4: Szorzók → | B4: ='⚙️ BEÁLLÍTÁSOK'!B41 -> 1.08 | C4: ='⚙️ BEÁLLÍTÁSOK'!B42 -> 1 | D4: ='⚙️ BEÁLLÍTÁSOK'!B43 -> 0.93 | E4: ='⚙️ BEÁLLÍTÁSOK'!B40 -> 1.15
A5: ──────── (A) NAPIBÉRES JELENLÉT – Bent vagyok, mint egy dolgozó ────────
A6: Ez a konstrukció akkor alkalmazandó, amikor egy generálkivitelező vagy megrendelő lényegében 'kölcsönzi' a kapacitásunkat – meghatározott időre, helyszínen. Fix óradíj, havi/negyedéves elszámolás.
A7: 🖥️ IT – Üzemeltetés, helpdesk, hálózat (helyszíni jelenlét) | B7: =ROUND('⚙️ BEÁLLÍTÁSOK'!B26*'⚙️ BEÁLLÍTÁSOK'!B41/'⚙️ BEÁLLÍTÁSOK'!B42/100,0)*100 -> 12400 | C7: =ROUND('⚙️ BEÁLLÍTÁSOK'!B26*'⚙️ BEÁLLÍTÁSOK'!B42/100,0)*100 -> 11500 | D7: =ROUND('⚙️ BEÁLLÍTÁSOK'!B26*'⚙️ BEÁLLÍTÁSOK'!B43/100,0)*100 -> 10700 | E7: =ROUND('⚙️ BEÁLLÍTÁSOK'!B26*'⚙️ BEÁLLÍTÁSOK'!B40/100,0)*100 -> 13200 | F7: Napi jelenlét: szerver/hálózat/user support. Minimálisan 4 órás egység.
A8: 💻 IT – Szoftver, fejlesztés, architektúra (helyszíni) | B8: =ROUND('⚙️ BEÁLLÍTÁSOK'!B27*'⚙️ BEÁLLÍTÁSOK'!B41/'⚙️ BEÁLLÍTÁSOK'!B42/100,0)*100 -> 19000 | C8: =ROUND('⚙️ BEÁLLÍTÁSOK'!B27*'⚙️ BEÁLLÍTÁSOK'!B42/100,0)*100 -> 17600 | D8: =ROUND('⚙️ BEÁLLÍTÁSOK'!B27*'⚙️ BEÁLLÍTÁSOK'!B43/100,0)*100 -> 16300 | E8: =ROUND('⚙️ BEÁLLÍTÁSOK'!B27*'⚙️ BEÁLLÍTÁSOK'!B40/100,0)*100 -> 20200 | F8: Fejlesztési, integrációs jelenlét. Minimálisan fél nap.
A9: 📹 Biztonságtechnika – Szerelő (helyszíni, napibéres) | B9: =ROUND('⚙️ BEÁLLÍTÁSOK'!B28*'⚙️ BEÁLLÍTÁSOK'!B41/'⚙️ BEÁLLÍTÁSOK'!B42/100,0)*100 -> 13600 | C9: =ROUND('⚙️ BEÁLLÍTÁSOK'!B28*'⚙️ BEÁLLÍTÁSOK'!B42/100,0)*100 -> 12600 | D9: =ROUND('⚙️ BEÁLLÍTÁSOK'!B28*'⚙️ BEÁLLÍTÁSOK'!B43/100,0)*100 -> 11700 | E9: =ROUND('⚙️ BEÁLLÍTÁSOK'!B28*'⚙️ BEÁLLÍTÁSOK'!B40/100,0)*100 -> 14500 | F9: Kamera, riasztó, beléptetés, tűzjelző szerelése. Minimálisan 4 óra.
A10: 🔴 Tűzvédelem – Szerelő / technikus (helyszíni) | B10: =ROUND('⚙️ BEÁLLÍTÁSOK'!B30*'⚙️ BEÁLLÍTÁSOK'!B41/'⚙️ BEÁLLÍTÁSOK'!B42/100,0)*100 -> 12400 | C10: =ROUND('⚙️ BEÁLLÍTÁSOK'!B30*'⚙️ BEÁLLÍTÁSOK'!B42/100,0)*100 -> 11500 | D10: =ROUND('⚙️ BEÁLLÍTÁSOK'!B30*'⚙️ BEÁLLÍTÁSOK'!B43/100,0)*100 -> 10700 | E10: =ROUND('⚙️ BEÁLLÍTÁSOK'!B30*'⚙️ BEÁLLÍTÁSOK'!B40/100,0)*100 -> 13200 | F10: Tűzjelző, tűzgátló munkák. Minimálisan 4 óra.
A11: ⚡ Villanyszerelő – általános (helyszíni, napibéres) | B11: =ROUND('⚙️ BEÁLLÍTÁSOK'!B32*'⚙️ BEÁLLÍTÁSOK'!B41/'⚙️ BEÁLLÍTÁSOK'!B42/100,0)*100 -> 12000 | C11: =ROUND('⚙️ BEÁLLÍTÁSOK'!B32*'⚙️ BEÁLLÍTÁSOK'!B42/100,0)*100 -> 11100 | D11: =ROUND('⚙️ BEÁLLÍTÁSOK'!B32*'⚙️ BEÁLLÍTÁSOK'!B43/100,0)*100 -> 10300 | E11: =ROUND('⚙️ BEÁLLÍTÁSOK'!B32*'⚙️ BEÁLLÍTÁSOK'!B40/100,0)*100 -> 12800 | F11: Általános villamos munkák. Minimálisan 4 óra.
A12: ⚡ Villanyszerelő – ipari / EV töltő (helyszíni) | B12: =ROUND('⚙️ BEÁLLÍTÁSOK'!B33*'⚙️ BEÁLLÍTÁSOK'!B41/'⚙️ BEÁLLÍTÁSOK'!B42/100,0)*100 -> 14000 | C12: =ROUND('⚙️ BEÁLLÍTÁSOK'!B33*'⚙️ BEÁLLÍTÁSOK'!B42/100,0)*100 -> 13000 | D12: =ROUND('⚙️ BEÁLLÍTÁSOK'!B33*'⚙️ BEÁLLÍTÁSOK'!B43/100,0)*100 -> 12000 | E12: =ROUND('⚙️ BEÁLLÍTÁSOK'!B33*'⚙️ BEÁLLÍTÁSOK'!B40/100,0)*100 -> 14900 | F12: Ipari gépbekötés, EV rendszer. Minimálisan 4 óra.
A14: ──────── (B) PROJEKT ALAPÚ ALVÁLLALKOZÓI MUNKA – Saját projekt, alvállalkozói minőségben ────────
A15: Ez a konstrukció akkor alkalmazandó, amikor SIROTECH saját projekt keretében vesz részt, de generálkivitelező alá tartozva. Fix tételes ár helyett óradíj – a tételes munkát a mátrix tartalmazza, ez az óradíjas keretegyezményhez.
A16: 🖥️ IT – Üzemeltetés / hálózat (projekt, alváll.) | B16: =ROUND('⚙️ BEÁLLÍTÁSOK'!B26*'⚙️ BEÁLLÍTÁSOK'!B41/'⚙️ BEÁLLÍTÁSOK'!B42/100,0)*100 -> 12400 | C16: =ROUND('⚙️ BEÁLLÍTÁSOK'!B26*'⚙️ BEÁLLÍTÁSOK'!B42/100,0)*100 -> 11500 | D16: =ROUND('⚙️ BEÁLLÍTÁSOK'!B26*'⚙️ BEÁLLÍTÁSOK'!B43/100,0)*100 -> 10700 | E16: =ROUND('⚙️ BEÁLLÍTÁSOK'!B26*'⚙️ BEÁLLÍTÁSOK'!B40/100,0)*100 -> 13200 | F16: Projekt keretek között, óradíj alapon. Minden óra dokumentált.
A17: 💻 IT – Fejlesztés (projekt, alvállalkozói) | B17: =ROUND('⚙️ BEÁLLÍTÁSOK'!B27*'⚙️ BEÁLLÍTÁSOK'!B41/'⚙️ BEÁLLÍTÁSOK'!B42/100,0)*100 -> 19000 | C17: =ROUND('⚙️ BEÁLLÍTÁSOK'!B27*'⚙️ BEÁLLÍTÁSOK'!B42/100,0)*100 -> 17600 | D17: =ROUND('⚙️ BEÁLLÍTÁSOK'!B27*'⚙️ BEÁLLÍTÁSOK'!B43/100,0)*100 -> 16300 | E17: =ROUND('⚙️ BEÁLLÍTÁSOK'!B27*'⚙️ BEÁLLÍTÁSOK'!B40/100,0)*100 -> 20200
A18: 📹 Biztonságtechnika – szerelő (projekt, alváll.) | B18: =ROUND('⚙️ BEÁLLÍTÁSOK'!B28*'⚙️ BEÁLLÍTÁSOK'!B41/'⚙️ BEÁLLÍTÁSOK'!B42/100,0)*100 -> 13600 | C18: =ROUND('⚙️ BEÁLLÍTÁSOK'!B28*'⚙️ BEÁLLÍTÁSOK'!B42/100,0)*100 -> 12600 | D18: =ROUND('⚙️ BEÁLLÍTÁSOK'!B28*'⚙️ BEÁLLÍTÁSOK'!B43/100,0)*100 -> 11700 | E18: =ROUND('⚙️ BEÁLLÍTÁSOK'!B28*'⚙️ BEÁLLÍTÁSOK'!B40/100,0)*100 -> 14500
A19: 📹 Biztonságtechnika – tervező / PM (projekt) | B19: =ROUND('⚙️ BEÁLLÍTÁSOK'!B29*'⚙️ BEÁLLÍTÁSOK'!B41/'⚙️ BEÁLLÍTÁSOK'!B42/100,0)*100 -> 15000 | C19: =ROUND('⚙️ BEÁLLÍTÁSOK'!B29*'⚙️ BEÁLLÍTÁSOK'!B42/100,0)*100 -> 13900 | D19: =ROUND('⚙️ BEÁLLÍTÁSOK'!B29*'⚙️ BEÁLLÍTÁSOK'!B43/100,0)*100 -> 12900 | E19: =ROUND('⚙️ BEÁLLÍTÁSOK'!B29*'⚙️ BEÁLLÍTÁSOK'!B40/100,0)*100 -> 16000
A20: 🔴 Tűzvédelem – szerelő (projekt, alváll.) | B20: =ROUND('⚙️ BEÁLLÍTÁSOK'!B30*'⚙️ BEÁLLÍTÁSOK'!B41/'⚙️ BEÁLLÍTÁSOK'!B42/100,0)*100 -> 12400 | C20: =ROUND('⚙️ BEÁLLÍTÁSOK'!B30*'⚙️ BEÁLLÍTÁSOK'!B42/100,0)*100 -> 11500 | D20: =ROUND('⚙️ BEÁLLÍTÁSOK'!B30*'⚙️ BEÁLLÍTÁSOK'!B43/100,0)*100 -> 10700 | E20: =ROUND('⚙️ BEÁLLÍTÁSOK'!B30*'⚙️ BEÁLLÍTÁSOK'!B40/100,0)*100 -> 13200
A21: 🔴 Tűzvédelem – tervező (projekt, alváll.) | B21: =ROUND('⚙️ BEÁLLÍTÁSOK'!B31*'⚙️ BEÁLLÍTÁSOK'!B41/'⚙️ BEÁLLÍTÁSOK'!B42/100,0)*100 -> 16400 | C21: =ROUND('⚙️ BEÁLLÍTÁSOK'!B31*'⚙️ BEÁLLÍTÁSOK'!B42/100,0)*100 -> 15200 | D21: =ROUND('⚙️ BEÁLLÍTÁSOK'!B31*'⚙️ BEÁLLÍTÁSOK'!B43/100,0)*100 -> 14100 | E21: =ROUND('⚙️ BEÁLLÍTÁSOK'!B31*'⚙️ BEÁLLÍTÁSOK'!B40/100,0)*100 -> 17400
A22: ⚡ Villanyszerelő (projekt, alvállalkozói) | B22: =ROUND('⚙️ BEÁLLÍTÁSOK'!B32*'⚙️ BEÁLLÍTÁSOK'!B41/'⚙️ BEÁLLÍTÁSOK'!B42/100,0)*100 -> 12000 | C22: =ROUND('⚙️ BEÁLLÍTÁSOK'!B32*'⚙️ BEÁLLÍTÁSOK'!B42/100,0)*100 -> 11100 | D22: =ROUND('⚙️ BEÁLLÍTÁSOK'!B32*'⚙️ BEÁLLÍTÁSOK'!B43/100,0)*100 -> 10300 | E22: =ROUND('⚙️ BEÁLLÍTÁSOK'!B32*'⚙️ BEÁLLÍTÁSOK'!B40/100,0)*100 -> 12800
A23: 📋 Projektmenedzsment / koordináció (alváll.) | B23: =ROUND('⚙️ BEÁLLÍTÁSOK'!B34*'⚙️ BEÁLLÍTÁSOK'!B41/'⚙️ BEÁLLÍTÁSOK'!B42/100,0)*100 -> 17000 | C23: =ROUND('⚙️ BEÁLLÍTÁSOK'!B34*'⚙️ BEÁLLÍTÁSOK'!B42/100,0)*100 -> 15700 | D23: =ROUND('⚙️ BEÁLLÍTÁSOK'!B34*'⚙️ BEÁLLÍTÁSOK'!B43/100,0)*100 -> 14600 | E23: =ROUND('⚙️ BEÁLLÍTÁSOK'!B34*'⚙️ BEÁLLÍTÁSOK'!B40/100,0)*100 -> 18100 | F23: Koordináció, átadás-átvétel, dokumentáció
A24: 🎓 Tanácsadás / audit / tréning (alváll.) | B24: =ROUND('⚙️ BEÁLLÍTÁSOK'!B35*'⚙️ BEÁLLÍTÁSOK'!B41/'⚙️ BEÁLLÍTÁSOK'!B42/100,0)*100 -> 23000 | C24: =ROUND('⚙️ BEÁLLÍTÁSOK'!B35*'⚙️ BEÁLLÍTÁSOK'!B42/100,0)*100 -> 21300 | D24: =ROUND('⚙️ BEÁLLÍTÁSOK'!B35*'⚙️ BEÁLLÍTÁSOK'!B43/100,0)*100 -> 19800 | E24: =ROUND('⚙️ BEÁLLÍTÁSOK'!B35*'⚙️ BEÁLLÍTÁSOK'!B40/100,0)*100 -> 24500 | F24: NIS2, tűzvédelem, IT bizt. tanácsadás
A26: ELSZÁMOLÁSI SZABÁLYOK: │ Minimális egység: 4 óra (napibéres: egész nap) │ Pótmunka: minden el nem tervezett feladat írásos befogadás után számolható │ Anyag mindig külön │ Fizetési feltétel: generálkivitelező fizetéséhez kötött (back-to-back)

Sheet 📅 SZERZ. SÁVOK
A1: 📅 SIROTECH – SZERZŐDÉSES IDŐ SÁVOK | MSP és havidíjas szolgáltatások | Nettó Ft/hó
A2: Az 1 éves szerz. = listaár (referencia). Havi/eseti = +15% rugalmassági felár. 2 éves = -7% kedvezmény. Kék cella = 1 éves alap ár (módosítható).
A3: Szolgáltatás | B3: Havi / eseti (Ft/hó) | C3: 6 hónapos szerz. (Ft/hó) | D3: 1 éves szerz. (Ft/hó) ALAP | E3: 2 éves szerz. (Ft/hó) | F3: Éves megtakarítás (2 év vs. havi) | G3: Felmondási feltételek
A4: Szorzók → | B4: ='⚙️ BEÁLLÍTÁSOK'!B40 -> 1.15 | C4: ='⚙️ BEÁLLÍTÁSOK'!B41 -> 1.08 | D4: ='⚙️ BEÁLLÍTÁSOK'!B42 -> 1 | E4: ='⚙️ BEÁLLÍTÁSOK'!B43 -> 0.93
A5: 🖥️ IT RENDSZERÜZEMELTETÉS
A6: Mikro csomag – 1–3 gép, remote | B6: =ROUND(D6*'⚙️ BEÁLLÍTÁSOK'!B40/100,0)*100 -> 27600 | C6: =ROUND(D6*'⚙️ BEÁLLÍTÁSOK'!B41/100,0)*100 -> 25900 | D6: 24000 | E6: =ROUND(D6*'⚙️ BEÁLLÍTÁSOK'!B43/100,0)*100 -> 22300 | F6: =ROUND((B6-E6)*12,0) -> 63600 | G6: 15 nap / 30 nap / 30 nap / 60 nap felmondás
A7: Alap csomag – 4–8 gép, remote | B7: =ROUND(D7*'⚙️ BEÁLLÍTÁSOK'!B40/100,0)*100 -> 59800 | C7: =ROUND(D7*'⚙️ BEÁLLÍTÁSOK'!B41/100,0)*100 -> 56200 | D7: 52000 | E7: =ROUND(D7*'⚙️ BEÁLLÍTÁSOK'!B43/100,0)*100 -> 48400 | F7: =ROUND((B7-E7)*12,0) -> 136800 | G7: Korai felbontás: maradék 50% / 30% / 25%
A8: Kis csomag – 9–15 gép, 1 kiszállás/hó | B8: =ROUND(D8*'⚙️ BEÁLLÍTÁSOK'!B40/100,0)*100 -> 112700 | C8: =ROUND(D8*'⚙️ BEÁLLÍTÁSOK'!B41/100,0)*100 -> 105800 | D8: 98000 | E8: =ROUND(D8*'⚙️ BEÁLLÍTÁSOK'!B43/100,0)*100 -> 91100 | F8: =ROUND((B8-E8)*12,0) -> 259200
A9: Közép csomag – 16–30 gép | B9: =ROUND(D9*'⚙️ BEÁLLÍTÁSOK'!B40/100,0)*100 -> 201200 | C9: =ROUND(D9*'⚙️ BEÁLLÍTÁSOK'!B41/100,0)*100 -> 189000 | D9: 175000 | E9: =ROUND(D9*'⚙️ BEÁLLÍTÁSOK'!B43/100,0)*100 -> 162800 | F9: =ROUND((B9-E9)*12,0) -> 460800
A10: Szerverszoba pótdíj | B10: =ROUND(D10*'⚙️ BEÁLLÍTÁSOK'!B40/100,0)*100 -> 28700 | C10: =ROUND(D10*'⚙️ BEÁLLÍTÁSOK'!B41/100,0)*100 -> 27000 | D10: 25000 | E10: =ROUND(D10*'⚙️ BEÁLLÍTÁSOK'!B43/100,0)*100 -> 23300 | F10: =ROUND((B10-E10)*12,0) -> 64800
A11: 🔒 NIS2 ÉS MEGFELELŐSÉG
A12: NIS2 folyamatos megfelelés felügyelet | B12: =ROUND(D12*'⚙️ BEÁLLÍTÁSOK'!B40/100,0)*100 -> 161000 | C12: =ROUND(D12*'⚙️ BEÁLLÍTÁSOK'!B41/100,0)*100 -> 151200 | D12: 140000 | E12: =ROUND(D12*'⚙️ BEÁLLÍTÁSOK'!B43/100,0)*100 -> 130200 | F12: =ROUND((B12-E12)*12,0) -> 369600 | G12: Áremelési záradék 2 éves szerz.-nél (KSH inf.)
A13: GDPR audit folyamatos felügyelet | B13: =ROUND(D13*'⚙️ BEÁLLÍTÁSOK'!B40/100,0)*100 -> 51700 | C13: =ROUND(D13*'⚙️ BEÁLLÍTÁSOK'!B41/100,0)*100 -> 48600 | D13: 45000 | E13: =ROUND(D13*'⚙️ BEÁLLÍTÁSOK'!B43/100,0)*100 -> 41900 | F13: =ROUND((B13-E13)*12,0) -> 117600
A14: 📹 BIZTONSÁGTECHNIKA – KARBANTARTÁS
A15: Kamerarendszer folyamatos felügyelet | B15: =ROUND(D15*'⚙️ BEÁLLÍTÁSOK'!B40/100,0)*100 -> 16100 | C15: =ROUND(D15*'⚙️ BEÁLLÍTÁSOK'!B41/100,0)*100 -> 15100 | D15: 14000 | E15: =ROUND(D15*'⚙️ BEÁLLÍTÁSOK'!B43/100,0)*100 -> 13000 | F15: =ROUND((B15-E15)*12,0) -> 37200 | G15: Negyedéves helyszíni kiszállás
A16: Riasztó folyamatos karbantartás | B16: =ROUND(D16*'⚙️ BEÁLLÍTÁSOK'!B40/100,0)*100 -> 12600 | C16: =ROUND(D16*'⚙️ BEÁLLÍTÁSOK'!B41/100,0)*100 -> 11900 | D16: 11000 | E16: =ROUND(D16*'⚙️ BEÁLLÍTÁSOK'!B43/100,0)*100 -> 10200 | F16: =ROUND((B16-E16)*12,0) -> 28800
A17: Tűzjelző folyamatos karbantartás + monitor | B17: =ROUND(D17*'⚙️ BEÁLLÍTÁSOK'!B40/100,0)*100 -> 25300 | C17: =ROUND(D17*'⚙️ BEÁLLÍTÁSOK'!B41/100,0)*100 -> 23800 | D17: 22000 | E17: =ROUND(D17*'⚙️ BEÁLLÍTÁSOK'!B43/100,0)*100 -> 20500 | F17: =ROUND((B17-E17)*12,0) -> 57600
A18: 💻 WEBOLDAL ÉS RENDSZER
A19: Weboldal karbantartás (frissítés + support) | B19: =ROUND(D19*'⚙️ BEÁLLÍTÁSOK'!B40/100,0)*100 -> 20700 | C19: =ROUND(D19*'⚙️ BEÁLLÍTÁSOK'!B41/100,0)*100 -> 19400 | D19: 18000 | E19: =ROUND(D19*'⚙️ BEÁLLÍTÁSOK'!B43/100,0)*100 -> 16700 | F19: =ROUND((B19-E19)*12,0) -> 48000
A20: Weboldal + hosting + SSL csomag | B20: =ROUND(D20*'⚙️ BEÁLLÍTÁSOK'!B40/100,0)*100 -> 29900 | C20: =ROUND(D20*'⚙️ BEÁLLÍTÁSOK'!B41/100,0)*100 -> 28100 | D20: 26000 | E20: =ROUND(D20*'⚙️ BEÁLLÍTÁSOK'!B43/100,0)*100 -> 24200 | F20: =ROUND((B20-E20)*12,0) -> 68400
A21: 📋 PROJEKT MEGBÍZOTTI / PM RETAINER
A22: PM retainer – havi jelenlét (8 óra keret) | B22: =ROUND(D22*'⚙️ BEÁLLÍTÁSOK'!B40/100,0)*100 -> 124200 | C22: =ROUND(D22*'⚙️ BEÁLLÍTÁSOK'!B41/100,0)*100 -> 116600 | D22: 108000 | E22: =ROUND(D22*'⚙️ BEÁLLÍTÁSOK'!B43/100,0)*100 -> 100400 | F22: =ROUND((B22-E22)*12,0) -> 285600 | G22: Túllépés: PM óradíjon elszámolva
A23: PM retainer – emelt (20 óra keret) | B23: =ROUND(D23*'⚙️ BEÁLLÍTÁSOK'!B40/100,0)*100 -> 270300 | C23: =ROUND(D23*'⚙️ BEÁLLÍTÁSOK'!B41/100,0)*100 -> 253800 | D23: 235000 | E23: =ROUND(D23*'⚙️ BEÁLLÍTÁSOK'!B43/100,0)*100 -> 218600 | F23: =ROUND((B23-E23)*12,0) -> 620400
A25: FELMONDÁSI FELTÉTELEK ÉS KÖTBÉR SZABÁLYOK
A26: Szerz. típus | B26: Felmondási idő | C26: Idő előtti felbontás | D26: Áremelési jog | E26: Indexálás
A27: Havi / eseti | B27: 15 napos | C27: Nincs kötbér | D27: Nincs | E27: Nincs
A28: 6 hónapos | B28: 30 napos | C28: Maradék 50%-a kötbérként | D28: Nincs | E28: Nincs
A29: 1 éves | B29: 30 napos | C29: Maradék 30%-a kötbérként | D29: Nem automatikus | E29: Max 5%/év, előzetes értesítéssel
A30: 2 éves | B30: 60 napos | C30: Maradék 25%-a kötbérként + éves felülvizsgálati pont | D30: KSH infláció mértékéig egyoldalúan | E30: Kötelező 2. évre

Sheet 🧮 KALKULÁTOR
A1: 🧮 SIROTECH – AJÁNLAT KALKULÁTOR | Töltsd ki a kék cellákat → automatikus számítás
A2: Overhead (rezsi + háttér bérek) a Beállítások lapon van beépítve. Anyagköltséget add hozzá külön. Sürgősségi szorzót alkalmaz automatikusan.
A4: ÜGYFÉL ADATOK – Az ajánlat alapadatai
A5: Ügyfél neve / cégnév
A6: Ügyfél típusa | B6: KKV
A7: Szerz. időtartam | B7: 1 év
A8: Kapcsolattartó neve
A9: Ajánlat dátuma
A10: Ajánlat érvényessége (napokban) | B10: 30
A12: ÁRKALKULÁCIÓ BEÁLLÍTÁSOK
A13: Ügyfél szorzó (Beállítások lapról) | B13: 1 | C13: ← Beállítások lap B39–B47 szorzói közül válaszd ki
A14: Sürgősségi szorzó (ha nem sürgős: 1,00) | B14: 1 | C14: 1,30 / 1,50 / 1,75 / 2,00 – lásd Beállítások lap
A16: TÉTELEK
A17: Tétel / Szolgáltatás leírása | B17: Egység | C17: Menny. | D17: Belső egységár (Ft) | E17: Szorzók (auto) | F17: Ajánlati egységár (Ft)
E18: =$B$13*$B$14 -> 1 | F18: =IF(OR(D18="",C18=""),"",ROUND(C18*D18*E18/100,0)*100)
E19: =$B$13*$B$14 -> 1 | F19: =IF(OR(D19="",C19=""),"",ROUND(C19*D19*E19/100,0)*100)
E20: =$B$13*$B$14 -> 1 | F20: =IF(OR(D20="",C20=""),"",ROUND(C20*D20*E20/100,0)*100)
E21: =$B$13*$B$14 -> 1 | F21: =IF(OR(D21="",C21=""),"",ROUND(C21*D21*E21/100,0)*100)
E22: =$B$13*$B$14 -> 1 | F22: =IF(OR(D22="",C22=""),"",ROUND(C22*D22*E22/100,0)*100)
E23: =$B$13*$B$14 -> 1 | F23: =IF(OR(D23="",C23=""),"",ROUND(C23*D23*E23/100,0)*100)
E24: =$B$13*$B$14 -> 1 | F24: =IF(OR(D24="",C24=""),"",ROUND(C24*D24*E24/100,0)*100)
E25: =$B$13*$B$14 -> 1 | F25: =IF(OR(D25="",C25=""),"",ROUND(C25*D25*E25/100,0)*100)
E26: =$B$13*$B$14 -> 1 | F26: =IF(OR(D26="",C26=""),"",ROUND(C26*D26*E26/100,0)*100)
E27: =$B$13*$B$14 -> 1 | F27: =IF(OR(D27="",C27=""),"",ROUND(C27*D27*E27/100,0)*100)
E28: =$B$13*$B$14 -> 1 | F28: =IF(OR(D28="",C28=""),"",ROUND(C28*D28*E28/100,0)*100)
E29: =$B$13*$B$14 -> 1 | F29: =IF(OR(D29="",C29=""),"",ROUND(C29*D29*E29/100,0)*100)
... E42: =$B$13*$B$14 -> 1 | F42: =IF(OR(D42="",C42=""),"",ROUND(C42*D42*E42/100,0)*100)
A45: Részösszeg (munkadíj nettó) | F45: =SUMIF(F18:F43,">0") -> 0
A46: Anyagköltség nettó (kézzel add meg)
A47: Anyagkezelési pótlék (eseti: 12%) | F47: =IF(B46="","",ROUND(B46*'⚙️ BEÁLLÍTÁSOK'!B50,0))
A48: NETTÓ ÖSSZESEN | F48: =B45+IF(B46="",0,B46)+IF(B47="",0,B47) -> 0
A49: ÁFA (27%) | F49: =IF(B48="","",ROUND(B48*'⚙️ BEÁLLÍTÁSOK'!B62,0))
A50: BRUTTÓ VÉGÖSSZEG | F50: =IF(B48="","",B48+B49)
